Watching for file changes with StatReloader
[16/Sep/2025 19:33:26] "GET /api/health/ HTTP/1.1" 200 16
[16/Sep/2025 19:33:26] "GET / HTTP/1.1" 200 562
Not Found: /api/analytics/overview/
[16/Sep/2025 19:33:54] "GET /api/analytics/overview/ HTTP/1.1" 404 41088
Not Found: /api/analytics/overview/
[16/Sep/2025 19:35:22] "GET /api/analytics/overview/ HTTP/1.1" 404 41088
Not Found: /api/analytics/overview/
[16/Sep/2025 19:35:28] "GET /api/analytics/overview/ HTTP/1.1" 404 41088
/home/dev/Klynaa/backend/config/urls.py changed, reloading.
Performing system checks...

System check identified no issues (0 silenced).
September 16, 2025 - 19:32:54
Django version 4.2.24, using settings 'config.settings'
Starting development server at http://0.0.0.0:8000/
Quit the server with CONTROL-C.

Watching for file changes with StatReloader
[16/Sep/2025 19:37:16] "GET /api/analytics/overview/ HTTP/1.1" 200 1791
[16/Sep/2025 19:43:07] "OPTIONS /api/dashboard/overview/ HTTP/1.1" 200 0
[16/Sep/2025 19:43:07] "OPTIONS /api/dashboard/overview/ HTTP/1.1" 200 0
Not Found: /api/dashboard/overview/
[16/Sep/2025 19:43:08] "GET /api/dashboard/overview/ HTTP/1.1" 404 41088
Not Found: /api/dashboard/overview/
[16/Sep/2025 19:43:08] "GET /api/dashboard/overview/ HTTP/1.1" 404 41088
[16/Sep/2025 19:44:27] "OPTIONS /api/analytics/overview/ HTTP/1.1" 200 0
[16/Sep/2025 19:44:27] "GET /api/analytics/overview/ HTTP/1.1" 200 1791
[16/Sep/2025 19:45:41] "GET /api/analytics/overview/ HTTP/1.1" 200 1791
[16/Sep/2025 19:45:41] "GET /api/analytics/overview/ HTTP/1.1" 200 1791
[16/Sep/2025 19:46:08] "GET /api/analytics/overview/ HTTP/1.1" 200 1791
/home/dev/Klynaa/backend/apps/analytics/views.py changed, reloading.
Performing system checks...

System check identified no issues (0 silenced).
September 16, 2025 - 19:37:01
Django version 4.2.24, using settings 'config.settings'
Starting development server at http://0.0.0.0:8000/
Quit the server with CONTROL-C.

Watching for file changes with StatReloader
/home/dev/Klynaa/backend/apps/analytics/views.py changed, reloading.
Performing system checks...

System check identified no issues (0 silenced).
September 16, 2025 - 19:48:34
Django version 4.2.24, using settings 'config.settings'
Starting development server at http://0.0.0.0:8000/
Quit the server with CONTROL-C.

Watching for file changes with StatReloader
/home/dev/Klynaa/backend/apps/analytics/views.py changed, reloading.
Performing system checks...

System check identified no issues (0 silenced).
September 16, 2025 - 19:49:26
Django version 4.2.24, using settings 'config.settings'
Starting development server at http://0.0.0.0:8000/
Quit the server with CONTROL-C.

Watching for file changes with StatReloader
Exception in thread django-main-thread:
Traceback (most recent call last):
  File "/usr/lib/python3.12/threading.py", line 1073, in _bootstrap_inner
    self.run()
  File "/usr/lib/python3.12/threading.py", line 1010, in run
    self._target(*self._args, **self._kwargs)
  File "/home/dev/Klynaa/venv/lib/python3.12/site-packages/django/utils/autoreload.py", line 64, in wrapper
    fn(*args, **kwargs)
  File "/home/dev/Klynaa/venv/lib/python3.12/site-packages/django/core/management/commands/runserver.py", line 133, in inner_run
    self.check(display_num_errors=True)
  File "/home/dev/Klynaa/venv/lib/python3.12/site-packages/django/core/management/base.py", line 485, in check
    all_issues = checks.run_checks(
                 ^^^^^^^^^^^^^^^^^^
  File "/home/dev/Klynaa/venv/lib/python3.12/site-packages/django/core/checks/registry.py", line 88, in run_checks
    new_errors = check(app_configs=app_configs, databases=databases)
                 ^^^^^^^^^^^^^^^^^^^^^^^^^^^^^^^^^^^^^^^^^^^^^^^^^^^
  File "/home/dev/Klynaa/venv/lib/python3.12/site-packages/django/core/checks/urls.py", line 14, in check_url_config
    return check_resolver(resolver)
           ^^^^^^^^^^^^^^^^^^^^^^^^
  File "/home/dev/Klynaa/venv/lib/python3.12/site-packages/django/core/checks/urls.py", line 24, in check_resolver
    return check_method()
           ^^^^^^^^^^^^^^
  File "/home/dev/Klynaa/venv/lib/python3.12/site-packages/django/urls/resolvers.py", line 494, in check
    for pattern in self.url_patterns:
                   ^^^^^^^^^^^^^^^^^
  File "/home/dev/Klynaa/venv/lib/python3.12/site-packages/django/utils/functional.py", line 57, in __get__
    res = instance.__dict__[self.name] = self.func(instance)
                                         ^^^^^^^^^^^^^^^^^^^
  File "/home/dev/Klynaa/venv/lib/python3.12/site-packages/django/urls/resolvers.py", line 715, in url_patterns
    patterns = getattr(self.urlconf_module, "urlpatterns", self.urlconf_module)
                       ^^^^^^^^^^^^^^^^^^^
  File "/home/dev/Klynaa/venv/lib/python3.12/site-packages/django/utils/functional.py", line 57, in __get__
    res = instance.__dict__[self.name] = self.func(instance)
                                         ^^^^^^^^^^^^^^^^^^^
  File "/home/dev/Klynaa/venv/lib/python3.12/site-packages/django/urls/resolvers.py", line 708, in urlconf_module
    return import_module(self.urlconf_name)
           ^^^^^^^^^^^^^^^^^^^^^^^^^^^^^^^^
  File "/usr/lib/python3.12/importlib/__init__.py", line 90, in import_module
    return _bootstrap._gcd_import(name[level:], package, level)
           ^^^^^^^^^^^^^^^^^^^^^^^^^^^^^^^^^^^^^^^^^^^^^^^^^^^^
  File "<frozen importlib._bootstrap>", line 1387, in _gcd_import
  File "<frozen importlib._bootstrap>", line 1360, in _find_and_load
  File "<frozen importlib._bootstrap>", line 1331, in _find_and_load_unlocked
  File "<frozen importlib._bootstrap>", line 935, in _load_unlocked
  File "<frozen importlib._bootstrap_external>", line 995, in exec_module
  File "<frozen importlib._bootstrap>", line 488, in _call_with_frames_removed
  File "/home/dev/Klynaa/backend/config/urls.py", line 48, in <module>
    path("api/analytics/", include("apps.analytics.urls")),
                           ^^^^^^^^^^^^^^^^^^^^^^^^^^^^^^
  File "/home/dev/Klynaa/venv/lib/python3.12/site-packages/django/urls/conf.py", line 38, in include
    urlconf_module = import_module(urlconf_module)
                     ^^^^^^^^^^^^^^^^^^^^^^^^^^^^^
  File "/usr/lib/python3.12/importlib/__init__.py", line 90, in import_module
    return _bootstrap._gcd_import(name[level:], package, level)
           ^^^^^^^^^^^^^^^^^^^^^^^^^^^^^^^^^^^^^^^^^^^^^^^^^^^^
  File "<frozen importlib._bootstrap>", line 1387, in _gcd_import
  File "<frozen importlib._bootstrap>", line 1360, in _find_and_load
  File "<frozen importlib._bootstrap>", line 1331, in _find_and_load_unlocked
  File "<frozen importlib._bootstrap>", line 935, in _load_unlocked
  File "<frozen importlib._bootstrap_external>", line 995, in exec_module
  File "<frozen importlib._bootstrap>", line 488, in _call_with_frames_removed
  File "/home/dev/Klynaa/backend/apps/analytics/urls.py", line 2, in <module>
    from . import views
  File "/home/dev/Klynaa/backend/apps/analytics/views.py", line 86
    "totalEarnings": {
                     ^
SyntaxError: '{' was never closed
/home/dev/Klynaa/backend/apps/analytics/views.py changed, reloading.
Performing system checks...

Watching for file changes with StatReloader
Exception in thread django-main-thread:
Traceback (most recent call last):
  File "/usr/lib/python3.12/threading.py", line 1073, in _bootstrap_inner
    self.run()
  File "/usr/lib/python3.12/threading.py", line 1010, in run
    self._target(*self._args, **self._kwargs)
  File "/home/dev/Klynaa/venv/lib/python3.12/site-packages/django/utils/autoreload.py", line 64, in wrapper
    fn(*args, **kwargs)
  File "/home/dev/Klynaa/venv/lib/python3.12/site-packages/django/core/management/commands/runserver.py", line 133, in inner_run
    self.check(display_num_errors=True)
  File "/home/dev/Klynaa/venv/lib/python3.12/site-packages/django/core/management/base.py", line 485, in check
    all_issues = checks.run_checks(
                 ^^^^^^^^^^^^^^^^^^
  File "/home/dev/Klynaa/venv/lib/python3.12/site-packages/django/core/checks/registry.py", line 88, in run_checks
    new_errors = check(app_configs=app_configs, databases=databases)
                 ^^^^^^^^^^^^^^^^^^^^^^^^^^^^^^^^^^^^^^^^^^^^^^^^^^^
  File "/home/dev/Klynaa/venv/lib/python3.12/site-packages/django/core/checks/urls.py", line 14, in check_url_config
    return check_resolver(resolver)
           ^^^^^^^^^^^^^^^^^^^^^^^^
  File "/home/dev/Klynaa/venv/lib/python3.12/site-packages/django/core/checks/urls.py", line 24, in check_resolver
    return check_method()
           ^^^^^^^^^^^^^^
  File "/home/dev/Klynaa/venv/lib/python3.12/site-packages/django/urls/resolvers.py", line 494, in check
    for pattern in self.url_patterns:
                   ^^^^^^^^^^^^^^^^^
  File "/home/dev/Klynaa/venv/lib/python3.12/site-packages/django/utils/functional.py", line 57, in __get__
    res = instance.__dict__[self.name] = self.func(instance)
                                         ^^^^^^^^^^^^^^^^^^^
  File "/home/dev/Klynaa/venv/lib/python3.12/site-packages/django/urls/resolvers.py", line 715, in url_patterns
    patterns = getattr(self.urlconf_module, "urlpatterns", self.urlconf_module)
                       ^^^^^^^^^^^^^^^^^^^
  File "/home/dev/Klynaa/venv/lib/python3.12/site-packages/django/utils/functional.py", line 57, in __get__
    res = instance.__dict__[self.name] = self.func(instance)
                                         ^^^^^^^^^^^^^^^^^^^
  File "/home/dev/Klynaa/venv/lib/python3.12/site-packages/django/urls/resolvers.py", line 708, in urlconf_module
    return import_module(self.urlconf_name)
           ^^^^^^^^^^^^^^^^^^^^^^^^^^^^^^^^
  File "/usr/lib/python3.12/importlib/__init__.py", line 90, in import_module
    return _bootstrap._gcd_import(name[level:], package, level)
           ^^^^^^^^^^^^^^^^^^^^^^^^^^^^^^^^^^^^^^^^^^^^^^^^^^^^
  File "<frozen importlib._bootstrap>", line 1387, in _gcd_import
  File "<frozen importlib._bootstrap>", line 1360, in _find_and_load
  File "<frozen importlib._bootstrap>", line 1331, in _find_and_load_unlocked
  File "<frozen importlib._bootstrap>", line 935, in _load_unlocked
  File "<frozen importlib._bootstrap_external>", line 995, in exec_module
  File "<frozen importlib._bootstrap>", line 488, in _call_with_frames_removed
  File "/home/dev/Klynaa/backend/config/urls.py", line 48, in <module>
    path("api/analytics/", include("apps.analytics.urls")),
                           ^^^^^^^^^^^^^^^^^^^^^^^^^^^^^^
  File "/home/dev/Klynaa/venv/lib/python3.12/site-packages/django/urls/conf.py", line 38, in include
    urlconf_module = import_module(urlconf_module)
                     ^^^^^^^^^^^^^^^^^^^^^^^^^^^^^
  File "/usr/lib/python3.12/importlib/__init__.py", line 90, in import_module
    return _bootstrap._gcd_import(name[level:], package, level)
           ^^^^^^^^^^^^^^^^^^^^^^^^^^^^^^^^^^^^^^^^^^^^^^^^^^^^
  File "<frozen importlib._bootstrap>", line 1387, in _gcd_import
  File "<frozen importlib._bootstrap>", line 1360, in _find_and_load
  File "<frozen importlib._bootstrap>", line 1331, in _find_and_load_unlocked
  File "<frozen importlib._bootstrap>", line 935, in _load_unlocked
  File "<frozen importlib._bootstrap_external>", line 995, in exec_module
  File "<frozen importlib._bootstrap>", line 488, in _call_with_frames_removed
  File "/home/dev/Klynaa/backend/apps/analytics/urls.py", line 2, in <module>
    from . import views
  File "/home/dev/Klynaa/backend/apps/analytics/views.py", line 106
    },
IndentationError: unexpected indent
/home/dev/Klynaa/backend/apps/analytics/views.py changed, reloading.
Performing system checks...

Watching for file changes with StatReloader
/home/dev/Klynaa/backend/apps/analytics/views.py changed, reloading.
Performing system checks...

System check identified no issues (0 silenced).
September 16, 2025 - 19:51:08
Django version 4.2.24, using settings 'config.settings'
Starting development server at http://0.0.0.0:8000/
Quit the server with CONTROL-C.

Watching for file changes with StatReloader
/home/dev/Klynaa/backend/apps/analytics/views.py changed, reloading.
Performing system checks...

System check identified no issues (0 silenced).
September 16, 2025 - 19:51:39
Django version 4.2.24, using settings 'config.settings'
Starting development server at http://0.0.0.0:8000/
Quit the server with CONTROL-C.

Watching for file changes with StatReloader
/home/dev/Klynaa/backend/apps/analytics/views.py changed, reloading.
Performing system checks...

System check identified no issues (0 silenced).
September 16, 2025 - 19:52:04
Django version 4.2.24, using settings 'config.settings'
Starting development server at http://0.0.0.0:8000/
Quit the server with CONTROL-C.

Watching for file changes with StatReloader
/home/dev/Klynaa/backend/apps/analytics/views.py changed, reloading.
Performing system checks...

System check identified no issues (0 silenced).
September 16, 2025 - 19:52:34
Django version 4.2.24, using settings 'config.settings'
Starting development server at http://0.0.0.0:8000/
Quit the server with CONTROL-C.

Watching for file changes with StatReloader
/home/dev/Klynaa/backend/apps/analytics/views.py changed, reloading.
Performing system checks...

System check identified no issues (0 silenced).
September 16, 2025 - 19:53:11
Django version 4.2.24, using settings 'config.settings'
Starting development server at http://0.0.0.0:8000/
Quit the server with CONTROL-C.

Watching for file changes with StatReloader
/home/dev/Klynaa/backend/apps/analytics/views.py changed, reloading.
Performing system checks...

System check identified no issues (0 silenced).
September 16, 2025 - 19:54:47
Django version 4.2.24, using settings 'config.settings'
Starting development server at http://0.0.0.0:8000/
Quit the server with CONTROL-C.

Watching for file changes with StatReloader
/home/dev/Klynaa/backend/apps/analytics/views.py changed, reloading.
Performing system checks...

System check identified no issues (0 silenced).
September 16, 2025 - 19:55:32
Django version 4.2.24, using settings 'config.settings'
Starting development server at http://0.0.0.0:8000/
Quit the server with CONTROL-C.

Watching for file changes with StatReloader
/home/dev/Klynaa/backend/apps/analytics/views.py changed, reloading.
Performing system checks...

System check identified no issues (0 silenced).
September 16, 2025 - 19:56:09
Django version 4.2.24, using settings 'config.settings'
Starting development server at http://0.0.0.0:8000/
Quit the server with CONTROL-C.

Watching for file changes with StatReloader
/home/dev/Klynaa/backend/apps/analytics/views.py changed, reloading.
Performing system checks...

System check identified no issues (0 silenced).
September 16, 2025 - 19:56:33
Django version 4.2.24, using settings 'config.settings'
Starting development server at http://0.0.0.0:8000/
Quit the server with CONTROL-C.

Watching for file changes with StatReloader
[16/Sep/2025 19:57:15] "GET /api/analytics/overview/ HTTP/1.1" 200 2164
[16/Sep/2025 19:57:33] "GET /api/analytics/overview/ HTTP/1.1" 200 2164
[16/Sep/2025 19:57:43] "GET /api/analytics/overview/ HTTP/1.1" 200 2164
[16/Sep/2025 20:04:57] "GET /api/analytics/overview/ HTTP/1.1" 200 2164
[16/Sep/2025 20:04:57] "GET /api/analytics/overview/ HTTP/1.1" 200 2164
[16/Sep/2025 20:14:29] "GET /api/analytics/overview/ HTTP/1.1" 200 2164
[16/Sep/2025 20:15:49] "GET /api/analytics/overview/ HTTP/1.1" 200 2164
[16/Sep/2025 20:20:44] "GET /api/analytics/overview/ HTTP/1.1" 200 2164
[16/Sep/2025 20:20:44] "GET /api/analytics/overview/ HTTP/1.1" 200 2164
[16/Sep/2025 20:20:47] "GET /api/analytics/overview/ HTTP/1.1" 200 2164
[16/Sep/2025 20:20:47] "GET /api/analytics/overview/ HTTP/1.1" 200 2164
[16/Sep/2025 20:22:27] "GET /api/analytics/overview/ HTTP/1.1" 200 2164
[16/Sep/2025 20:22:55] "GET /api/analytics/overview/ HTTP/1.1" 200 2164
[16/Sep/2025 20:26:21] "GET /api/analytics/overview/ HTTP/1.1" 200 2164
[16/Sep/2025 20:34:09] "GET /api/health/ HTTP/1.1" 200 16
[16/Sep/2025 20:39:03] "GET /api/analytics/overview/ HTTP/1.1" 200 2164
[16/Sep/2025 20:39:03] "GET /api/analytics/overview/ HTTP/1.1" 200 2164
[16/Sep/2025 20:43:33] "GET /api/analytics/overview/ HTTP/1.1" 200 2164
[16/Sep/2025 20:44:21] "GET /api/analytics/overview/ HTTP/1.1" 200 2164
[16/Sep/2025 21:02:23] "GET /api/analytics/overview/ HTTP/1.1" 200 2164
[16/Sep/2025 21:02:23] "GET /api/analytics/overview/ HTTP/1.1" 200 2164
